Encountered an error: Compilation Error in model stg_model (models/example/stg_model.sql)   Model 'model.my_new_project.stg_model' (models/example/stg_model.sql) depends on a source named 'in.c-test-bucket.test' which was not found Traceback (most recent call last):   File "/usr/local/lib/python3.9/dist-packages/dbt/main.py", line 129, in main     results, succeeded = handle_and_check(args)   File "/usr/local/lib/python3.9/dist-packages/dbt/main.py", line 191, in handle_and_check     task, res = run_from_args(parsed)   File "/usr/local/lib/python3.9/dist-packages/dbt/main.py", line 238, in run_from_args     results = task.run()   File "/usr/local/lib/python3.9/dist-packages/dbt/task/runnable.py", line 451, in run     self._runtime_initialize()   File "/usr/local/lib/python3.9/dist-packages/dbt/task/runnable.py", line 159, in _runtime_initialize     super()._runtime_initialize()   File "/usr/local/lib/python3.9/dist-packages/dbt/task/runnable.py", line 92, in _runtime_initialize     self.load_manifest()   File "/usr/local/lib/python3.9/dist-packages/dbt/task/runnable.py", line 81, in load_manifest     self.manifest = ManifestLoader.get_full_manifest(self.config)   File "/usr/local/lib/python3.9/dist-packages/dbt/parser/manifest.py", line 219, in get_full_manifest     manifest = loader.load()   File "/usr/local/lib/python3.9/dist-packages/dbt/parser/manifest.py", line 390, in load     self.process_sources(self.root_project.project_name)   File "/usr/local/lib/python3.9/dist-packages/dbt/parser/manifest.py", line 921, in process_sources     _process_sources_for_node(self.manifest, current_project, node)   File "/usr/local/lib/python3.9/dist-packages/dbt/parser/manifest.py", line 1302, in _process_sources_for_node     invalid_source_fail_unless_test(   File "/usr/local/lib/python3.9/dist-packages/dbt/parser/manifest.py", line 955, in invalid_source_fail_unless_test     source_target_not_found(node, target_name, target_table_name, disabled=disabled)   File "/usr/local/lib/python3.9/dist-packages/dbt/exceptions.py", line 656, in source_target_not_found     raise_compiler_error(msg, model)   File "/usr/local/lib/python3.9/dist-packages/dbt/exceptions.py", line 445, in raise_compiler_error     raise CompilationException(msg, node) dbt.exceptions.CompilationException: Compilation Error in model stg_model (models/example/stg_model.sql)   Model 'model.my_new_project.stg_model' (models/example/stg_model.sql) depends on a source named 'in.c-test-bucket.test' which was not found